Workbook

Sheet Northstar Dashboard
B2: NORTHSTAR RETAIL LTD.
B4: UK Sales & Profit Performance | 2024–2025 Executive Dashboard
B6: TOTAL SALES | F6: TOTAL PROFIT | J6: PROFIT MARGIN | N6: TOTAL ORDERS | R6: AVG ORDER VALUE
B7: =Analyses!B5 -> 1379032.2 | F7: =Analyses!B6 -> 578786.2 | J7: =Analyses!B8 -> 0.41970463 | N7: =Analyses!B7 -> 10000 | R7: =Analyses!B9 -> 137.90322
B8: ="▲ "&TEXT(Analyses!B16,"0.0%")&" YoY" -> ▲ 2.2% YoY | F8: ="▲ "&TEXT(Analyses!B17,"0.0%")&" YoY" -> ▲ 1.6% YoY | J8: of total sales | N8: Jan 2024 – Dec 2025 | R8: per order, all channels
B11: MONTHLY SALES & PROFIT TREND — 2024 vs 2025 | K11: NEW vs RETURNING CUSTOMERS
R12: ="New-customer orders fell from "&TEXT(Analyses!F60,"#,##0")&" in 2024 to just "&TEXT(Analyses!G60,"#,##0")&" in 2025, while returning-customer orders grew from "&TEXT(Analyses!F61,"#,##0")&" to "&TEXT(Analyses!G61,"#,##0")&". Returning customers now drive the vast majority of volume — average order value is almost identical between the two groups (£"&TEXT(Analyses!E60,"0.00")&" new vs £"&TEXT(Analyses!E61,"0.00")&" returning), so the shift is about acquisition, not spend per order." -> New-customer orders fell from 1,632 in 2024 to just 160 in 2025, while returning-customer orders grew from 3,347 to 4,861. Returning customers now drive the vast majority of volume — average order value is almost identical between the two groups (£138.06 new vs £137.87 returning), so the shift is about acquisition, not spend per order.
B29: REVENUE & PROFIT BY CATEGORY | K29: REVENUE & PROFIT BY REGION (in DESC order)
B58: TOP 10 PRODUCTS BY REVENUE | K58: TOP 10 CUSTOMERS BY REVENUE
B82: AVERAGE ORDER VALUE — QUICK COMPARISON (overall: see AVG ORDER VALUE tile above)
B83: HIGHEST AOV — REGION | G83: LOWEST AOV — REGION | L83: NEW CUSTOMERS | Q83: RETURNING CUSTOMERS
B84: =INDEX(Analyses!$A$45:$A$56,MATCH(MAX(Analyses!$F$45:$F$56),Analyses!$F$45:$F$56,0))&" · £"&TEXT(MAX(Analyses!$F$45:$F$56),"0.00") -> Wales · £143.03 | G84: =INDEX(Analyses!$A$45:$A$56,MATCH(MIN(Analyses!$F$45:$F$56),Analyses!$F$45:$F$56,0))&" · £"&TEXT(MIN(Analyses!$F$45:$F$56),"0.00") -> Northern Ireland · £133.06 | L84: ="£"&TEXT(Analyses!E60,"0.00") -> £138.06 | Q84: ="£"&TEXT(Analyses!E61,"0.00") -> £137.87
B87: KEY INSIGHT: UNDERPERFORMING AREAS | K87: TOP 3 RECOMMENDATIONS FOR MANAGEMENT
B88: ="1. "&Analyses!B131&" and "&Analyses!B132&" are the weakest-profit regions, at £"&TEXT(Analyses!C131,"#,##0")&" and £"&TEXT(Analyses!C132,"#,##0")&" profit — they also have the fewest orders of any region ("&TEXT(Analyses!D131,"#,##0")&" and "&TEXT(Analyses!D132,"#,##0")&"), so the shortfall tracks a smaller customer base rather than a weaker margin."&CHAR(10)&CHAR(10)&"2. The Books category brings in the least revenue and profit of all six categories: £"&TEXT(Analyses!B41,"#,##0")&" revenue and £"&TEXT(Analyses!C41,"#,##0")&" profit, versus a category average of £"&TEXT(AVERAGE(Analyses!B36:B41),"#,##0")&" revenue — a persistent laggard across both years."&CHAR(10)&CHAR(10)&"3. New-customer order volume collapsed from "&TEXT(Analyses!F60,"#,##0")&" orders in 2024 to just "&TEXT(Analyses!G60,"#,##0")&" in 2025 (returning-customer orders grew over the same period), pointing to a stalled acquisition funnel rather than a retention problem." -> 1. North East and Northern Ireland are the weakest-profit regions, at £18,948 and £24,191 profit — they also have the fewest orders of any region (331 and 433), so the shortfall tracks a smaller customer base rather than a weaker margin. 2. The Books category brings in the least revenue and profit of all six categories: £70,759 revenue and £36,121 profit, versus a category average of £229,839 revenue — a persistent laggard across both years. 3. New-customer order volume collapsed from 1,632 orders in 2024 to just 160 in 2025 (returning-customer orders grew over the same period), pointing to a stalled acquisition funnel rather than a retention problem. | K88: 1. Investigate and rebuild new-customer acquisition. Orders from new customers dropped over 90% year-on-year while returning-customer volume rose — check tracking/attribution first, then marketing spend and channel mix, since average order value is unaffected (spend per order is not the issue). 2. Prioritise Electronics and Sports & Outdoors over Home & Kitchen in promotions and stock investment. Home & Kitchen drives the most revenue but converts it to profit at the lowest margin of the top categories — shifting mix toward higher-margin lines lifts profit without needing more sales. 3. Run a focused regional push in North East and Northern Ireland. Both regions carry margins in line with the rest of the country, so the gap is volume, not pricing — a local acquisition or partnership campaign should close it faster than a national one.
B107: ="Source: Raw_Data (10,000 orders, Jan 2024 – Dec 2025, Northstar Retail Ltd., UK). All figures calculated live with SUMIFS / COUNTIFS / AVERAGEIFS — recalculates automatically as Raw_Data changes. Built "&TEXT(TODAY(),"dd mmm yyyy")&"." -> Source: Raw_Data (10,000 orders, Jan 2024 – Dec 2025, Northstar Retail Ltd., UK). All figures calculated live with SUMIFS / COUNTIFS / AVERAGEIFS — recalculates automatically as Raw_Data changes. Built 14 Sep 2026.

Sheet Analyses
A1: DASHBOARD_DATA — live calculations feeding the Northstar Dashboard (SUMIFS / COUNTIFS / AVERAGEIFS against Raw_Data). Do not delete.
A3: KPIs
A4: Metric | B4: Value
A5: Total Sales | B5: =SUM(Raw_Data!$Q$2:$Q$10001) -> 1379032.2
A6: Total Profit | B6: =SUM(Raw_Data!$S$2:$S$10001) -> 578786.2
A7: Total Orders | B7: =COUNTA(Raw_Data!$A$2:$A$10001) -> 10000
A8: Profit Margin | B8: =B6/B5 -> 0.41970463
A9: Average Order Value | B9: =B5/B7 -> 137.90322
A10: Sales 2024 | B10: =SUMIFS(Raw_Data!$Q$2:$Q$10001,Raw_Data!$D$2:$D$10001,2024) -> 681963.85
A11: Sales 2025 | B11: =SUMIFS(Raw_Data!$Q$2:$Q$10001,Raw_Data!$D$2:$D$10001,2025) -> 697068.35
A12: Profit 2024 | B12: =SUMIFS(Raw_Data!$S$2:$S$10001,Raw_Data!$D$2:$D$10001,2024) -> 287105.85
A13: Profit 2025 | B13: =SUMIFS(Raw_Data!$S$2:$S$10001,Raw_Data!$D$2:$D$10001,2025) -> 291680.35
A14: Orders 2024 | B14: =COUNTIFS(Raw_Data!$D$2:$D$10001,2024) -> 4979
A15: Orders 2025 | B15: =COUNTIFS(Raw_Data!$D$2:$D$10001,2025) -> 5021
A16: Sales YoY Growth | B16: =(B11-B10)/B10 -> 0.022148535
A17: Profit YoY Growth | B17: =(B13-B12)/B12 -> 0.015933148
A19: Monthly Sales & Profit Trend (2024 vs 2025)
A20: Month | B20: MonthNum | C20: Sales 2024 | D20: Profit 2024 | E20: Sales 2025 | F20: Profit 2025
A21: Jan | B21: 1 | C21: =SUMIFS(Raw_Data!$Q$2:$Q$10001,Raw_Data!$C$2:$C$10001,$B21,Raw_Data!$D$2:$D$10001,2024) -> 60412.2 | D21: =SUMIFS(Raw_Data!$S$2:$S$10001,Raw_Data!$C$2:$C$10001,$B21,Raw_Data!$D$2:$D$10001,2024) -> 25707.2 | E21: =SUMIFS(Raw_Data!$Q$2:$Q$10001,Raw_Data!$C$2:$C$10001,$B21,Raw_Data!$D$2:$D$10001,2025) -> 55687.75 | F21: =SUMIFS(Raw_Data!$S$2:$S$10001,Raw_Data!$C$2:$C$10001,$B21,Raw_Data!$D$2:$D$10001,2025) -> 23709.75
A22: Feb | B22: 2 | C22: =SUMIFS(Raw_Data!$Q$2:$Q$10001,Raw_Data!$C$2:$C$10001,$B22,Raw_Data!$D$2:$D$10001,2024) -> 53040.75 | D22: =SUMIFS(Raw_Data!$S$2:$S$10001,Raw_Data!$C$2:$C$10001,$B22,Raw_Data!$D$2:$D$10001,2024) -> 22433.75 | E22: =SUMIFS(Raw_Data!$Q$2:$Q$10001,Raw_Data!$C$2:$C$10001,$B22,Raw_Data!$D$2:$D$10001,2025) -> 51382.85 | F22: =SUMIFS(Raw_Data!$S$2:$S$10001,Raw_Data!$C$2:$C$10001,$B22,Raw_Data!$D$2:$D$10001,2025) -> 21445.85
A23: Mar | B23: 3 | C23: =SUMIFS(Raw_Data!$Q$2:$Q$10001,Raw_Data!$C$2:$C$10001,$B23,Raw_Data!$D$2:$D$10001,2024) -> 58274.6 | D23: =SUMIFS(Raw_Data!$S$2:$S$10001,Raw_Data!$C$2:$C$10001,$B23,Raw_Data!$D$2:$D$10001,2024) -> 24658.6 | E23: =SUMIFS(Raw_Data!$Q$2:$Q$10001,Raw_Data!$C$2:$C$10001,$B23,Raw_Data!$D$2:$D$10001,2025) -> 57232.25 | F23: =SUMIFS(Raw_Data!$S$2:$S$10001,Raw_Data!$C$2:$C$10001,$B23,Raw_Data!$D$2:$D$10001,2025) -> 24199.25
A24: Apr | B24: 4 | C24: =SUMIFS(Raw_Data!$Q$2:$Q$10001,Raw_Data!$C$2:$C$10001,$B24,Raw_Data!$D$2:$D$10001,2024) -> 56158.2 | D24: =SUMIFS(Raw_Data!$S$2:$S$10001,Raw_Data!$C$2:$C$10001,$B24,Raw_Data!$D$2:$D$10001,2024) -> 23643.2 | E24: =SUMIFS(Raw_Data!$Q$2:$Q$10001,Raw_Data!$C$2:$C$10001,$B24,Raw_Data!$D$2:$D$10001,2025) -> 56452.85 | F24: =SUMIFS(Raw_Data!$S$2:$S$10001,Raw_Data!$C$2:$C$10001,$B24,Raw_Data!$D$2:$D$10001,2025) -> 23771.85
A25: May | B25: 5 | C25: =SUMIFS(Raw_Data!$Q$2:$Q$10001,Raw_Data!$C$2:$C$10001,$B25,Raw_Data!$D$2:$D$10001,2024) -> 57463 | D25: =SUMIFS(Raw_Data!$S$2:$S$10001,Raw_Data!$C$2:$C$10001,$B25,Raw_Data!$D$2:$D$10001,2024) -> 24184 | E25: =SUMIFS(Raw_Data!$Q$2:$Q$10001,Raw_Data!$C$2:$C$10001,$B25,Raw_Data!$D$2:$D$10001,2025) -> 59003.75 | F25: =SUMIFS(Raw_Data!$S$2:$S$10001,Raw_Data!$C$2:$C$10001,$B25,Raw_Data!$D$2:$D$10001,2025) -> 24274.75
A26: Jun | B26: 6 | C26: =SUMIFS(Raw_Data!$Q$2:$Q$10001,Raw_Data!$C$2:$C$10001,$B26,Raw_Data!$D$2:$D$10001,2024) -> 54621.6 | D26: =SUMIFS(Raw_Data!$S$2:$S$10001,Raw_Data!$C$2:$C$10001,$B26,Raw_Data!$D$2:$D$10001,2024) -> 23185.6 | E26: =SUMIFS(Raw_Data!$Q$2:$Q$10001,Raw_Data!$C$2:$C$10001,$B26,Raw_Data!$D$2:$D$10001,2025) -> 60369.45 | F26: =SUMIFS(Raw_Data!$S$2:$S$10001,Raw_Data!$C$2:$C$10001,$B26,Raw_Data!$D$2:$D$10001,2025) -> 25790.45
A27: Jul | B27: 7 | C27: =SUMIFS(Raw_Data!$Q$2:$Q$10001,Raw_Data!$C$2:$C$10001,$B27,Raw_Data!$D$2:$D$10001,2024) -> 55448 | D27: =SUMIFS(Raw_Data!$S$2:$S$10001,Raw_Data!$C$2:$C$10001,$B27,Raw_Data!$D$2:$D$10001,2024) -> 23386 | E27: =SUMIFS(Raw_Data!$Q$2:$Q$10001,Raw_Data!$C$2:$C$10001,$B27,Raw_Data!$D$2:$D$10001,2025) -> 69073.15 | F27: =SUMIFS(Raw_Data!$S$2:$S$10001,Raw_Data!$C$2:$C$10001,$B27,Raw_Data!$D$2:$D$10001,2025) -> 28587.15
A28: Aug | B28: 8 | C28: =SUMIFS(Raw_Data!$Q$2:$Q$10001,Raw_Data!$C$2:$C$10001,$B28,Raw_Data!$D$2:$D$10001,2024) -> 59605.65 | D28: =SUMIFS(Raw_Data!$S$2:$S$10001,Raw_Data!$C$2:$C$10001,$B28,Raw_Data!$D$2:$D$10001,2024) -> 24611.65 | E28: =SUMIFS(Raw_Data!$Q$2:$Q$10001,Raw_Data!$C$2:$C$10001,$B28,Raw_Data!$D$2:$D$10001,2025) -> 64069.8 | F28: =SUMIFS(Raw_Data!$S$2:$S$10001,Raw_Data!$C$2:$C$10001,$B28,Raw_Data!$D$2:$D$10001,2025) -> 26275.8
A29: Sep | B29: 9 | C29: =SUMIFS(Raw_Data!$Q$2:$Q$10001,Raw_Data!$C$2:$C$10001,$B29,Raw_Data!$D$2:$D$10001,2024) -> 57993.6 | D29: =SUMIFS(Raw_Data!$S$2:$S$10001,Raw_Data!$C$2:$C$10001,$B29,Raw_Data!$D$2:$D$10001,2024) -> 24078.6 | E29: =SUMIFS(Raw_Data!$Q$2:$Q$10001,Raw_Data!$C$2:$C$10001,$B29,Raw_Data!$D$2:$D$10001,2025) -> 56125.1 | F29: =SUMIFS(Raw_Data!$S$2:$S$10001,Raw_Data!$C$2:$C$10001,$B29,Raw_Data!$D$2:$D$10001,2025) -> 23377.1
A30: Oct | B30: 10 | C30: =SUMIFS(Raw_Data!$Q$2:$Q$10001,Raw_Data!$C$2:$C$10001,$B30,Raw_Data!$D$2:$D$10001,2024) -> 57469.55 | D30: =SUMIFS(Raw_Data!$S$2:$S$10001,Raw_Data!$C$2:$C$10001,$B30,Raw_Data!$D$2:$D$10001,2024) -> 23992.55 | E30: =SUMIFS(Raw_Data!$Q$2:$Q$10001,Raw_Data!$C$2:$C$10001,$B30,Raw_Data!$D$2:$D$10001,2025) -> 59904.25 | F30: =SUMIFS(Raw_Data!$S$2:$S$10001,Raw_Data!$C$2:$C$10001,$B30,Raw_Data!$D$2:$D$10001,2025) -> 25084.25
A31: Nov | B31: 11 | C31: =SUMIFS(Raw_Data!$Q$2:$Q$10001,Raw_Data!$C$2:$C$10001,$B31,Raw_Data!$D$2:$D$10001,2024) -> 51314.45 | D31: =SUMIFS(Raw_Data!$S$2:$S$10001,Raw_Data!$C$2:$C$10001,$B31,Raw_Data!$D$2:$D$10001,2024) -> 21695.45 | E31: =SUMIFS(Raw_Data!$Q$2:$Q$10001,Raw_Data!$C$2:$C$10001,$B31,Raw_Data!$D$2:$D$10001,2025) -> 55638.1 | F31: =SUMIFS(Raw_Data!$S$2:$S$10001,Raw_Data!$C$2:$C$10001,$B31,Raw_Data!$D$2:$D$10001,2025) -> 23157.1
A32: Dec | B32: 12 | C32: =SUMIFS(Raw_Data!$Q$2:$Q$10001,Raw_Data!$C$2:$C$10001,$B32,Raw_Data!$D$2:$D$10001,2024) -> 60162.25 | D32: =SUMIFS(Raw_Data!$S$2:$S$10001,Raw_Data!$C$2:$C$10001,$B32,Raw_Data!$D$2:$D$10001,2024) -> 25529.25 | E32: =SUMIFS(Raw_Data!$Q$2:$Q$10001,Raw_Data!$C$2:$C$10001,$B32,Raw_Data!$D$2:$D$10001,2025) -> 52129.05 | F32: =SUMIFS(Raw_Data!$S$2:$S$10001,Raw_Data!$C$2:$C$10001,$B32,Raw_Data!$D$2:$D$10001,2025) -> 22007.05
A34: Revenue & Profit by Category
A35: Category | B35: Sales | C35: Profit | D35: Margin | E35: Orders | F35: AOV
A36: Home & Kitchen | B36: =SUMIFS(Raw_Data!$Q$2:$Q$10001,Raw_Data!$L$2:$L$10001,$A36) -> 365777.75 | C36: =SUMIFS(Raw_Data!$S$2:$S$10001,Raw_Data!$L$2:$L$10001,$A36) -> 123953.75 | D36: =C36/B36 -> 0.33887723 | E36: =COUNTIFS(Raw_Data!$L$2:$L$10001,$A36) -> 1610 | F36: =B36/E36 -> 227.19115
A37: Electronics | B37: =SUMIFS(Raw_Data!$Q$2:$Q$10001,Raw_Data!$L$2:$L$10001,$A37) -> 318914.5 | C37: =SUMIFS(Raw_Data!$S$2:$S$10001,Raw_Data!$L$2:$L$10001,$A37) -> 127054.5 | D37: =C37/B37 -> 0.39839675 | E37: =COUNTIFS(Raw_Data!$L$2:$L$10001,$A37) -> 1948 | F37: =B37/E37 -> 163.71381
A38: Clothing | B38: =SUMIFS(Raw_Data!$Q$2:$Q$10001,Raw_Data!$L$2:$L$10001,$A38) -> 227862.2 | C38: =SUMIFS(Raw_Data!$S$2:$S$10001,Raw_Data!$L$2:$L$10001,$A38) -> 105704.2 | D38: =C38/B38 -> 0.46389528 | E38: =COUNTIFS(Raw_Data!$L$2:$L$10001,$A38) -> 1862 | F38: =B38/E38 -> 122.37497
A39: Sports & Outdoors | B39: =SUMIFS(Raw_Data!$Q$2:$Q$10001,Raw_Data!$L$2:$L$10001,$A39) -> 216911.15 | C39: =SUMIFS(Raw_Data!$S$2:$S$10001,Raw_Data!$L$2:$L$10001,$A39) -> 93851.15 | D39: =C39/B39 -> 0.43267093 | E39: =COUNTIFS(Raw_Data!$L$2:$L$10001,$A39) -> 1709 | F39: =B39/E39 -> 126.92285
A40: Beauty | B40: =SUMIFS(Raw_Data!$Q$2:$Q$10001,Raw_Data!$L$2:$L$10001,$A40) -> 178807.9 | C40: =SUMIFS(Raw_Data!$S$2:$S$10001,Raw_Data!$L$2:$L$10001,$A40) -> 92101.9 | D40: =C40/B40 -> 0.51508854 | E40: =COUNTIFS(Raw_Data!$L$2:$L$10001,$A40) -> 1607 | F40: =B40/E40 -> 111.26814
A41: Books | B41: =SUMIFS(Raw_Data!$Q$2:$Q$10001,Raw_Data!$L$2:$L$10001,$A41) -> 70758.7 | C41: =SUMIFS(Raw_Data!$S$2:$S$10001,Raw_Data!$L$2:$L$10001,$A41) -> 36120.7 | D41: =C41/B41 -> 0.51047716 | E41: =COUNTIFS(Raw_Data!$L$2:$L$10001,$A41) -> 1264 | F41: =B41/E41 -> 55.979984
A43: Revenue & Profit by Region
A44: Region | B44: Sales | C44: Profit | D44: Margin | E44: Orders | F44: AOV
...

Sheet Project_Brief
A1: Project Information | B1: Details
A2: Company | B2: Northstar Retail Ltd.
A3: Industry | B3: General retail / e-commerce
A4: Market | B4: United Kingdom
A5: Analysis Period | B5: 2024–2025
A6: Objective | B6: Analyse sales performance, profitability, customer behaviour and regional performance.
A7: Primary Deliverable | B7: Interactive Excel management dashboard with findings and recommendations.
A8: Recommended Tools | B8: Power Query, Excel Tables, PivotTables, PivotCharts, XLOOKUP, SUMIFS, COUNTIFS, AVERAGEIFS
A11: Question_No | B11: Business_Question
A12: 1 | B12: What were total revenue, total profit and overall profit margin in 2024 and 2025?
A13: 2 | B13: How did monthly revenue and profit change over the two-year period?
A14: 3 | B14: Which product categories generate the most revenue?
A15: 4 | B15: Which product categories generate the most profit?
A16: 5 | B16: Which 10 products generate the most revenue, and which 10 generate the most profit?
A17: 6 | B17: Which regions generate the most revenue and profit?
A18: 7 | B18: Which regions have the strongest and weakest profit margins?
A19: 8 | B19: How many customers are new vs returning, and how do their orders, revenue and average order value compare?
A20: 9 | B20: Who are the top 10 customers by revenue, and how much revenue/profit do they generate?
A21: 10 | B21: What is the average order value, and how does it vary by region, customer type and category?
A22: 11 | B22: Which areas of the business appear to be underperforming? Identify at least three.
A23: 12 | B23: What are your top three recommendations for management based on the evidence?

Sheet Raw_Data
A1: Order_ID | B1: Order_Date | C1: MONTH | D1: YEAR | E1: 2024 by month | F1: Customer_ID | G1: Customer_Name | H1: Region | I1: City | J1: Product_ID | K1: Product_Name | L1: Category | M1: Quantity | N1: Unit_Price | O1: Unit_Cost | P1: Discount | Q1: Sales | R1: Cost | S1: Profit | T1: Payment_Method | U1: Customer_Type | X1: UNIQUE CUSTOMER | Y1: 2024 CUSTOMERS | AA1: 2025 customers
A2: O00082 | B2: 45292 | C2: 1 | D2: 2024 | F2: C0260 | G2: Alex Adams | H2: East Midlands | I2: Derby | J2: P013 | K2: Winter Jacket | L2: Clothing | M2: 2 | N2: 120 | O2: 63 | P2: 0 | Q2: 240 | R2: 126 | S2: 114 | T2: ['Bank Transfer' 'Credit Card' 'PayPal' ... 'Credit Card' 'Bank Transfer' 'Apple Pay'] | U2: New | X2: {=_xlfn.UNIQUE(G2:G10001)} -> Alex Adams | Y2: {=_xlfn.UNIQUE(G2:G4980)} -> Alex Adams | Z2: {=_xlfn.UNIQUE(G4981:G10001)} -> Oscar Wilson
A3: O00178 | B3: 45292 | C3: 1 | D3: 2024 | F3: C0260 | G3: Alex Adams | H3: East Midlands | I3: Derby | J3: P009 | K3: Running Shoes | L3: Sports & Outdoors | M3: 1 | N3: 95 | O3: 54 | P3: 0.05 | Q3: 90.25 | R3: 54 | S3: 36.25 | T3: ['Bank Transfer' 'Credit Card' 'PayPal' ... 'Credit Card' 'Bank Transfer' 'Apple Pay'] | U3: New | X3: Oscar White | Y3: Oscar White | Z3: Daniel Carter
A4: O00992 | B4: 45292 | C4: 1 | D4: 2024 | F4: C0465 | G4: Oscar White | H4: North West | I4: Preston | J4: P023 | K4: Cookbook Collection | L4: Books | M4: 3 | N4: 42 | O4: 20 | P4: 0.15 | Q4: 107.1 | R4: 60 | S4: 47.1 | T4: ['Bank Transfer' 'Credit Card' 'PayPal' ... 'Credit Card' 'Bank Transfer' 'Apple Pay'] | U4: New | X4: Sophie Smith | Y4: Sophie Smith | Z4: Jessica Walker
A5: O01597 | B5: 45292 | C5: 1 | D5: 2024 | F5: C0061 | G5: Sophie Smith | H5: London | I5: London | J5: P005 | K5: Air Fryer | L5: Home & Kitchen | M5: 1 | N5: 119 | O5: 72 | P5: 0 | Q5: 119 | R5: 72 | S5: 47 | T5: ['Bank Transfer' 'Credit Card' 'PayPal' ... 'Credit Card' 'Bank Transfer' 'Apple Pay'] | U5: New | X5: Emma Brown | Y5: Emma Brown | Z5: Jack Walker
A6: O01796 | B6: 45292 | C6: 1 | D6: 2024 | F6: C0175 | G6: Emma Brown | H6: South East | I6: Guildford | J6: P016 | K6: Sneakers | L6: Clothing | M6: 5 | N6: 78 | O6: 39 | P6: 0 | Q6: 390 | R6: 195 | S6: 195 | T6: ['Bank Transfer' 'Credit Card' 'PayPal' ... 'Credit Card' 'Bank Transfer' 'Apple Pay'] | U6: New | X6: Harry Morgan | Y6: Harry Morgan | Z6: Alex Roberts
A7: O02114 | B7: 45292 | C7: 1 | D7: 2024 | F7: C0558 | G7: Harry Morgan | H7: Yorkshire & Humber | I7: Hull | J7: P018 | K7: Hair Care Bundle | L7: Beauty | M7: 1 | N7: 45 | O7: 19 | P7: 0.15 | Q7: 38.25 | R7: 19 | S7: 19.25 | T7: ['Bank Transfer' 'Credit Card' 'PayPal' ... 'Credit Card' 'Bank Transfer' 'Apple Pay'] | U7: New | X7: Alex Campbell | Y7: Alex Campbell | Z7: Olivia Evans
A8: O03420 | B8: 45292 | C8: 1 | D8: 2024 | F8: C1417 | G8: Alex Campbell | H8: Northern Ireland | I8: Belfast | J8: P013 | K8: Winter Jacket | L8: Clothing | M8: 2 | N8: 120 | O8: 63 | P8: 0.05 | Q8: 228 | R8: 126 | S8: 102 | T8: ['Bank Transfer' 'Credit Card' 'PayPal' ... 'Credit Card' 'Bank Transfer' 'Apple Pay'] | U8: New | X8: George Parker | Y8: George Parker | Z8: Emma Morgan
A9: O04289 | B9: 45292 | C9: 1 | D9: 2024 | F9: C0118 | G9: George Parker | H9: Northern Ireland | I9: Derry | J9: P011 | K9: Fitness Tracker | L9: Sports & Outdoors | M9: 1 | N9: 79 | O9: 42 | P9: 0 | Q9: 79 | R9: 42 | S9: 37 | T9: ['Bank Transfer' 'Credit Card' 'PayPal' ... 'Credit Card' 'Bank Transfer' 'Apple Pay'] | U9: New | X9: Jessica Brown | Y9: Jessica Brown | Z9: Oscar Walker
A10: O05558 | B10: 45292 | C10: 1 | D10: 2024 | F10: C0824 | G10: Jessica Brown | H10: Yorkshire & Humber | I10: York | J10: P013 | K10: Winter Jacket | L10: Clothing | M10: 2 | N10: 120 | O10: 63 | P10: 0 | Q10: 240 | R10: 126 | S10: 114 | T10: ['Bank Transfer' 'Credit Card' 'PayPal' ... 'Credit Card' 'Bank Transfer' 'Apple Pay'] | U10: New | X10: Noah Williams | Y10: Noah Williams | Z10: Jack Evans
A11: O06764 | B11: 45292 | C11: 1 | D11: 2024 | F11: C0344 | G11: Noah Williams | H11: Yorkshire & Humber | I11: York | J11: P018 | K11: Hair Care Bundle | L11: Beauty | M11: 1 | N11: 45 | O11: 19 | P11: 0 | Q11: 45 | R11: 19 | S11: 26 | T11: ['Bank Transfer' 'Credit Card' 'PayPal' ... 'Credit Card' 'Bank Transfer' 'Apple Pay'] | U11: New | X11: Ava Lewis | Y11: Ava Lewis | Z11: Grace Hughes
A12: O07105 | B12: 45292 | C12: 1 | D12: 2024 | F12: C1141 | G12: Ava Lewis | H12: South West | I12: Bath | J12: P007 | K12: Non-Stick Cookware Set | L12: Home & Kitchen | M12: 1 | N12: 129 | O12: 78 | P12: 0 | Q12: 129 | R12: 78 | S12: 51 | T12: ['Bank Transfer' 'Credit Card' 'PayPal' ... 'Credit Card' 'Bank Transfer' 'Apple Pay'] | U12: New | X12: Alex Thomas | Y12: Alex Thomas | Z12: Harry Clark
A13: O07711 | B13: 45292 | C13: 1 | D13: 2024 | F13: C0047 | G13: Alex Thomas | H13: South East | I13: Reading | J13: P022 | K13: Data Analytics Handbook | L13: Books | M13: 2 | N13: 35 | O13: 16 | P13: 0.15 | Q13: 59.5 | R13: 32 | S13: 27.5 | T13: ['Bank Transfer' 'Credit Card' 'PayPal' ... 'Credit Card' 'Bank Transfer' 'Apple Pay'] | U13: New | X13: Leo Jones | Y13: Leo Jones | Z13: Leo Lewis
A14: O07978 | B14: 45292 | C14: 1 | D14: 2024 | F14: C1658 | G14: Leo Jones | H14: London | I14: London | J14: P018 | K14: Hair Care Bundle | L14: Beauty | M14: 2 | N14: 45 | O14: 19 | P14: 0 | Q14: 90 | R14: 38 | S14: 52 | T14: ['Bank Transfer' 'Credit Card' 'PayPal' ... 'Credit Card' 'Bank Transfer' 'Apple Pay'] | U14: New | X14: Jack Mitchell | Y14: Jack Mitchell | Z14: Ava Baker
... A565: O06776 | B565: 45331 | C565: 2 | D565: 2024 | F565: C0132 | G565: Liam White | H565: Yorkshire & Humber | I565: Leeds | J565: P002 | K565: Smartwatch | L565: Electronics | M565: 2 | N565: 149 | O565: 91 | P565: 0.05 | Q565: 283.1 | R565: 182 | S565: 101.1 | T565: ['Bank Transfer' 'Credit Card' 'PayPal' ... 'Credit Card' 'Bank Transfer' 'Apple Pay'] | U565: New | X565: Daniel Lewis | Y565: Daniel Lewis | Z565: Jack Hall
A566: O07805 | B566: 45331 | C566: 2 | D566: 2024 | F566: C0644 | G566: Ava Lewis | H566: Northern Ireland | I566: Newry | J566: P013 | K566: Winter Jacket | L566: Clothing | M566: 2 | N566: 120 | O566: 63 | P566: 0.1 | Q566: 216 | R566: 126 | S566: 90 | T566: ['Bank Transfer' 'Credit Card' 'PayPal' ... 'Credit Card' 'Bank Transfer' 'Apple Pay'] | U566: New | X566: Leo Green | Y566: Leo Green
A567: O09604 | B567: 45331 | C567: 2 | D567: 2024 | F567: C0348 | G567: George Campbell | H567: Scotland | I567: Edinburgh | J567: P017 | K567: Skincare Set | L567: Beauty | M567: 1 | N567: 58 | O567: 25 | P567: 0.05 | Q567: 55.1 | R567: 25 | S567: 30.1 | T567: ['Bank Transfer' 'Credit Card' 'PayPal' ... 'Credit Card' 'Bank Transfer' 'Apple Pay'] | U567: New | X567: Noah Scott
A568: O00120 | B568: 45332 | C568: 2 | D568: 2024 | F568: C1539 | G568: Amelia Hall | H568: West Midlands | I568: Wolverhampton | J568: P014 | K568: Cotton T-Shirt | L568: Clothing | M568: 1 | N568: 25 | O568: 11 | P568: 0 | Q568: 25 | R568: 11 | S568: 14 | T568: ['Bank Transfer' 'Credit Card' 'PayPal' ... 'Credit Card' 'Bank Transfer' 'Apple Pay'] | U568: New | X568: Harry Davies
A569: O02335 | B569: 45332 | C569: 2 | D569: 2024 | F569: C0967 | G569: Amelia Hall | H569: East Midlands | I569: Lincoln | J569: P021 | K569: Business Strategy Book | L569: Books | M569: 1 | N569: 28 | O569: 13 | P569: 0.05 | Q569: 26.6 | R569: 13 | S569: 13.6 | T569: ['Bank Transfer' 'Credit Card' 'PayPal' ... 'Credit Card' 'Bank Transfer' 'Apple Pay'] | U569: Returning | X569: Isla Campbell
A570: O02621 | B570: 45332 | C570: 2 | D570: 2024 | F570: C0896 | G570: Liam Adams | H570: West Midlands | I570: Birmingham | J570: P023 | K570: Cookbook Collection | L570: Books | M570: 3 | N570: 42 | O570: 20 | P570: 0.1 | Q570: 113.4 | R570: 60 | S570: 53.4 | T570: ['Bank Transfer' 'Credit Card' 'PayPal' ... 'Credit Card' 'Bank Transfer' 'Apple Pay'] | U570: New | X570: Jack Taylor
A571: O03750 | B571: 45332 | C571: 2 | D571: 2024 | F571: C0024 | G571: Olivia Moore | H571: East of England | I571: Norwich | J571: P024 | K571: Personal Finance Guide | L571: Books | M571: 3 | N571: 24 | O571: 10 | P571: 0.05 | Q571: 68.4 | R571: 30 | S571: 38.4 | T571: ['Bank Transfer' 'Credit Card' 'PayPal' ... 'Credit Card' 'Bank Transfer' 'Apple Pay'] | U571: Returning | X571: Harry Lewis
A572: O05167 | B572: 45332 | C572: 2 | D572: 2024 | F572: C1005 | G572: Leo White | H572: Northern Ireland | I572: Belfast | J572: P021 | K572: Business Strategy Book | L572: Books | M572: 1 | N572: 28 | O572: 13 | P572: 0 | Q572: 28 | R572: 13 | S572: 15 | T572: ['Bank Transfer' 'Credit Card' 'PayPal' ... 'Credit Card' 'Bank Transfer' 'Apple Pay'] | U572: New | X572: Oscar Davies
A573: O05451 | B573: 45332 | C573: 2 | D573: 2024 | F573: C1333 | G573: Thomas Green | H573: North East | I573: Sunderland | J573: P023 | K573: Cookbook Collection | L573: Books | M573: 1 | N573: 42 | O573: 20 | P573: 0 | Q573: 42 | R573: 20 | S573: 22 | T573: ['Bank Transfer' 'Credit Card' 'PayPal' ... 'Credit Card' 'Bank Transfer' 'Apple Pay'] | U573: New
A574: O06321 | B574: 45332 | C574: 2 | D574: 2024 | F574: C0692 | G574: Noah Thomas | H574: East of England | I574: Cambridge | J574: P002 | K574: Smartwatch | L574: Electronics | M574: 1 | N574: 149 | O574: 91 | P574: 0.1 | Q574: 134.1 | R574: 91 | S574: 43.1 | T574: ['Bank Transfer' 'Credit Card' 'PayPal' ... 'Credit Card' 'Bank Transfer' 'Apple Pay'] | U574: New
A575: O08895 | B575: 45332 | C575: 2 | D575: 2024 | F575: C0114 | G575: Grace Smith | H575: South East | I575: Guildford | J575: P012 | K575: Camping Backpack | L575: Sports & Outdoors | M575: 1 | N575: 85 | O575: 44 | P575: 0.1 | Q575: 76.5 | R575: 44 | S575: 32.5 | T575: ['Bank Transfer' 'Credit Card' 'PayPal' ... 'Credit Card' 'Bank Transfer' 'Apple Pay'] | U575: Returning
A576: O08930 | B576: 45332 | C576: 2 | D576: 2024 | F576: C0745 | G576: Thomas Lewis | H576: East of England | I576: Norwich | J576: P002 | K576: Smartwatch | L576: Electronics | M576: 5 | N576: 149 | O576: 91 | P576: 0.1 | Q576: 670.5 | R576: 455 | S576: 215.5 | T576: ['Bank Transfer' 'Credit Card' 'PayPal' ... 'Credit Card' 'Bank Transfer' 'Apple Pay'] | U576: New
A577: O00131 | B577: 45333 | C577: 2 | D577: 2024 | F577: C0062 | G577: George Brown | H577: Wales | I577: Wrexham | J577: P022 | K577: Data Analytics Handbook | L577: Books | M577: 2 | N577: 35 | O577: 16 | P577: 0.1 | Q577: 63 | R577: 32 | S577: 31 | T577: ['Bank Transfer' 'Credit Card' 'PayPal' ... 'Credit Card' 'Bank Transfer' 'Apple Pay'] | U577: Returning
A578: O00426 | B578: 45333 | C578: 2 | D578: 2024 | F578: C0131 | G578: Isla Adams | H578: East Midlands | I578: Derby | J578: P021 | K578: Business Strategy Book | L578: Books | M578: 2 | N578: 28 | O578: 13 | P578: 0 | Q578: 56 | R578: 26 | S578: 30 | T578: ['Bank Transfer' 'Credit Card' 'PayPal' ... 'Credit Card' 'Bank Transfer' 'Apple Pay'] | U578: New
A579: O00580 | B579: 45333 | C579: 2 | D579: 2024 | F579: C0616 | G579: Leo Thomas | H579: East of England | I579: Ipswich | J579: P010 | K579: Yoga Mat | L579: Sports & Outdoors | M579: 2 | N579: 32 | O579: 14 | P579: 0 | Q579: 64 | R579: 28 | S579: 36 | T579: ['Bank Transfer' 'Credit Card' 'PayPal' ... 'Credit Card' 'Bank Transfer' 'Apple Pay'] | U579: New
A580: O01806 | B580: 45333 | C580: 2 | D580: 2024 | F580: C0509 | G580: Leo Adams | H580: South West | I580: Plymouth | J580: P017 | K580: Skincare Set | L580: Beauty | M580: 2 | N580: 58 | O580: 25 | P580: 0.05 | Q580: 110.2 | R580: 50 | S580: 60.2 | T580: ['Bank Transfer' 'Credit Card' 'PayPal' ... 'Credit Card' 'Bank Transfer' 'Apple Pay'] | U580: New
A581: O02077 | B581: 45333 | C581: 2 | D581: 2024 | F581: C0072 | G581: Jessica White | H581: Wales | I581: Newport | J581: P003 | K581: Bluetooth Speaker | L581: Electronics | M581: 2 | N581: 69 | O581: 37 | P581: 0 | Q581: 138 | R581: 74 | S581: 64 | T581: ['Bank Transfer' 'Credit Card' 'PayPal' ... 'Credit Card' 'Bank Transfer' 'Apple Pay'] | U581: Returning
A582: O02297 | B582: 45333 | C582: 2 | D582: 2024 | F582: C0162 | G582: Daniel Mitchell | H582: North East | I582: Durham | J582: P012 | K582: Camping Backpack | L582: Sports & Outdoors | M582: 3 | N582: 85 | O582: 44 | P582: 0.05 | Q582: 242.25 | R582: 132 | S582: 110.25 | T582: ['Bank Transfer' 'Credit Card' 'PayPal' ... 'Credit Card' 'Bank Transfer' 'Apple Pay'] | U582: Returning
A583: O03521 | B583: 45333 | C583: 2 | D583: 2024 | F583: C1210 | G583: George Hughes | H583: East of England | I583: Norwich | J583: P004 | K583: Laptop Stand | L583: Electronics | M583: 1 | N583: 55 | O583: 27 | P583: 0 | Q583: 55 | R583: 27 | S583: 28 | T583: ['Bank Transfer' 'Credit Card' 'PayPal' ... 'Credit Card' 'Bank Transfer' 'Apple Pay'] | U583: New
A584: O03859 | B584: 45333 | C584: 2 | D584: 2024 | F584: C1223 | G584: Noah Williams | H584: South West | I584: Exeter | J584: P012 | K584: Camping Backpack | L584: Sports & Outdoors | M584: 2 | N584: 85 | O584: 44 | P584: 0.05 | Q584: 161.5 | R584: 88 | S584: 73.5 | T584: ['Bank Transfer' 'Credit Card' 'PayPal' ... 'Credit Card' 'Bank Transfer' 'Apple Pay'] | U584: New
... A762: O02678 | B762: 45346 | C762: 2 | D762: 2024 | F762: C1706 | G762: Mia Baker | H762: North West | I762: Manchester | J762: P019 | K762: Perfume | L762: Beauty | M762: 4 | N762: 85 | O762: 41 | P762: 0.05 | Q762: 323 | R762: 164 | S762: 159 | T762: ['Bank Transfer' 'Credit Card' 'PayPal' ... 'Credit Card' 'Bank Transfer' 'Apple Pay'] | U762: Returning
A763: O02926 | B763: 45346 | C763: 2 | D763: 2024 | F763: C0503 | G763: Amelia Lewis | H763: Scotland | J763: P020 | K763: Electric Toothbrush | L763: Beauty | M763: 2 | N763: 72 | O763: 34 | P763: 0.1 | Q763: 129.6 | R763: 68 | S763: 61.6 | T763: ['Bank Transfer' 'Credit Card' 'PayPal' ... 'Credit Card' 'Bank Transfer' 'Apple Pay'] | U763: New
A764: O03286 | B764: 45346 | C764: 2 | D764: 2024 | F764: C1740 | G764: Mia Morgan | H764: London | I764: London | J764: P017 | K764: Skincare Set | L764: Beauty | M764: 1 | N764: 58 | O764: 25 | P764: 0.05 | Q764: 55.1 | R764: 25 | S764: 30.1 | T764: ['Bank Transfer' 'Credit Card' 'PayPal' ... 'Credit Card' 'Bank Transfer' 'Apple Pay'] | U764: New
A765: O04465 | B765: 45346 | C765: 2 | D765: 2024 | F765: C0095 | G765: Jack Wilson | H765: East Midlands | I765: Nottingham | J765: P002 | K765: Smartwatch | L765: Electronics | M765: 3 | N765: 149 | O765: 91 | P765: 0.1 | Q765: 402.3 | R765: 273 | S765: 129.3 | T765: ['Bank Transfer' 'Credit Card' 'PayPal' ... 'Credit Card' 'Bank Transfer' 'Apple Pay'] | U765: New
A766: O05856 | B766: 45346 | C766: 2 | D766: 2024 | F766: C0248 | G766: George Campbell | H766: Northern Ireland | I766: Newry | J766: P020 | K766: Electric Toothbrush | L766: Beauty | M766: 1 | N766: 72 | O766: 34 | P766: 0.15 | Q766: 61.2 | R766: 34 | S766: 27.2 | T766: ['Bank Transfer' 'Credit Card' 'PayPal' ... 'Credit Card' 'Bank Transfer' 'Apple Pay'] | U766: Returning
A767: O06630 | B767: 45346 | C767: 2 | D767: 2024 | F767: C0651 | G767: Jessica Hall | H767: South East | I767: Reading | J767: P020 | K767: Electric Toothbrush | L767: Beauty | M767: 1 | N767: 72 | O767: 34 | P767: 0 | Q767: 72 | R767: 34 | S767: 38 | T767: ['Bank Transfer' 'Credit Card' 'PayPal' ... 'Credit Card' 'Bank Transfer' 'Apple Pay'] | U767: New
...

Sheet CUSTOMER LIST
A1: UNIQUE CUSTOMER | B1: 2024 CUSTOMERS | C1: 2025 CUSTOMERS
A2: Alex Adams | B2: Alex Adams | C2: Alex Adams
A3: Alex Baker | B3: Alex Baker | C3: Alex Baker
A4: Alex Brown | B4: Alex Brown | C4: Alex Brown
A5: Alex Campbell | B5: Alex Campbell | C5: Alex Campbell
A6: Alex Clark | B6: Alex Clark | C6: Alex Clark
A7: Alex Evans | B7: Alex Evans | C7: Alex Evans
A8: Alex Green | B8: Alex Green | C8: Alex Green
A9: Alex Hall | B9: Alex Hall | C9: Alex Hughes
A10: Alex Hughes | B10: Alex Hughes | C10: Alex Jones
A11: Alex Jones | B11: Alex Jones | C11: Alex Kelly
A12: Alex Kelly | B12: Alex Kelly | C12: Alex Lewis
... A565: William Smith | B565: William Williams | C565: William Wilson
A566: William Taylor | B566: William Wilson
A567: William Thomas
A568: William Walker
A569: William Watson
A570: William White
A571: William Williams
A572: William Wilson

Sheet Table
A1: Row Labels | B1: Sum of Sales | C1: Sum of Profit
A2: Alex Smith | B2: 7795.9 | C2: 3214.9
A3: George Brown | B3: 7666.8 | C3: 3236.8
A4: Alex Evans | B4: 7534.25 | C4: 3152.25
A5: Daniel Parker | B5: 7479 | C5: 3075
A6: Oscar Harris | B6: 7311.8 | C6: 2994.8
A7: Noah Moore | B7: 7211.3 | C7: 3043.3
A8: Leo Thomas | B8: 7151.85 | C8: 2920.85
A9: Alex Martin | B9: 7045.65 | C9: 2875.65
A10: Sophie Jones | B10: 6742.4 | C10: 2870.4
A11: Jessica Walker | B11: 6641.7 | C11: 2834.7

Sheet Q8
A1: QUESTION 8: How many customers are new vs returning, and how do their orders, revenue and average order value compare?
A4: Count of Customer_Type | B4: Column Labels | G4: Insight: Orders from new customers fell sharply from 1,632 in 2024 to just 160 in 2025, while returning-customer orders increased from 3,347 to 4,861. Consequently, returning customers accounted for 96.8% of orders in 2025 compared with 67.2% in 2024. Despite this shift, average order value remained almost identical for new and returning customers at approximately £138 per order. The sharp decline in new-customer orders warrants further investigation into customer acquisition, marketing activity and customer classification.
A5: Row Labels | B5: 2024 | C5: 2025 | D5: Grand Total
A6: New | B6: 1632 | C6: 160 | D6: 1792
A7: Returning | B7: 3347 | C7: 4861 | D7: 8208
A8: Grand Total | B8: 4979 | C8: 5021 | D8: 10000
A11: Row Labels | B11: Sum of Sales | C11: Count of Order_ID | G11: On average, both new and returning customers spend about the same amount of money per order.
A12: New | B12: 247394.6 | C12: 1792 | D12: =AVERAGE(B12/C12) -> 138.05502
A13: Returning | B13: 1131637.6 | C13: 8208 | D13: =AVERAGE(B13/C13) -> 137.87008
A14: Grand Total | B14: 1379032.2 | C14: 10000
A18: Q9: Who are the top 10 customers by revenue, and how much revenue/profit do they generate?
B22: Values
A23: Row Labels | B23: Sum of Profit | C23: Count of Order_ID | D23: Sum of Sales
A24: Alex Smith | B24: 3214.9 | C24: 51 | D24: 7795.9
A25: George Brown | B25: 3236.8 | C25: 48 | D25: 7666.8
A26: Alex Evans | B26: 3152.25 | C26: 49 | D26: 7534.25
A27: Daniel Parker | B27: 3075 | C27: 45 | D27: 7479
A28: Oscar Harris | B28: 2994.8 | C28: 47 | D28: 7311.8
A29: Noah Moore | B29: 3043.3 | C29: 47 | D29: 7211.3
A30: Leo Thomas | B30: 2920.85 | C30: 57 | D30: 7151.85
A31: Alex Martin | B31: 2875.65 | C31: 36 | D31: 7045.65
A32: Sophie Jones | B32: 2870.4 | C32: 44 | D32: 6742.4
A33: Jessica Walker | B33: 2834.7 | C33: 50 | D33: 6641.7
A34: Amelia Hall | B34: 2569.9 | C34: 38 | D34: 6580.9
A35: Thomas Wilson | B35: 2727.75 | C35: 47 | D35: 6540.75
... A595: Grand Total | B595: 578786.2 | C595: 10000 | D595: 1379032.2

Sheet Q10
A1: Customer_Type | B1: (All)
A2: Category | B2: (All)
A4: Row Labels | B4: Sum of Sales | C4: Count of Order_ID | D4: Average Order Value
A5: East Midlands | B5: 97451.6 | C5: 722 | D5: =$B$5/$C$5 -> 134.97452 | F5: Question 10: What is the average order value, and how does it vary by region, customer type and category?
A6: East of England | B6: 99388.6 | C6: 745 | D6: =$B$6/$C$6 -> 133.40752
A7: London | B7: 249393.9 | C7: 1766 | D7: =$B$7/$C$7 -> 141.21965
A8: North East | B8: 45552.65 | C8: 331 | D8: =$B$8/$C$8 -> 137.6213
A9: North West | B9: 139876.35 | C9: 1051 | D9: =$B$9/$C$9 -> 133.08882
A10: Northern Ireland | B10: 57614.3 | C10: 433 | D10: =$B$10/$C$10 -> 133.05843
A11: Scotland | B11: 138986.7 | C11: 999 | D11: =$B$11/$C$11 -> 139.12583
A12: South East | B12: 146884.85 | C12: 1045 | D12: =$B$12/$C$12 -> 140.55967
A13: South West | B13: 86131.05 | C13: 630 | D13: =$B$13/$C$13 -> 136.71595
A14: Wales | B14: 84817.95 | C14: 593 | D14: =$B$14/$C$14 -> 143.03196
A15: West Midlands | B15: 92520.7 | C15: 668 | D15: =$B$15/$C$15 -> 138.50404
A16: Yorkshire & Humber | B16: 140413.55 | C16: 1017 | D16: =$B$16/$C$16 -> 138.06642
A17: Grand Total | B17: 1379032.2 | C17: 10000 | D17: =$B$17/$C$17 -> 137.90322

Sheet Q11
A2: q11 - Which areas of the business appear to be underperforming? Identify at least three.
A4: YEAR | B4: (All)
A6: Row Labels | B6: Sum of Profit | C6: Count of Customer_ID | D6: profit per customer
A7: North East | B7: 18947.65 | C7: 331 | D7: =$B$7/$C$7 -> 57.243656
A8: Northern Ireland | B8: 24191.3 | C8: 433 | D8: =$B$8/$C$8 -> 55.869053
A9: Wales | B9: 35548.95 | C9: 593 | D9: =$B$9/$C$9 -> 59.947639 | F9: Answer: On aggregate(2024 and 2025) North East and Northern Ireland regions are both underperforming at Total profit of $18k and $24k respectively. These regions also have the least number of customer orders. North East has 331 and 433 which leads to the creation and computation of the profit per order metric and Northern Ireland performs worse with $55.87 per order while North East has $57.24 per order
A10: South West | B10: 36297.05 | C10: 630 | D10: =$B$10/$C$10 -> 57.614365 | F10: This insight translates accurately onto total revenue. North East and Northern Ireland both perform the worst with $45k and $57k respectively, however sales per order is 137.62 for North East and $133.06 for Northern Ireland.
A11: West Midlands | B11: 39572.7 | C11: 668 | D11: =$B$11/$C$11 -> 59.240569
A12: East Midlands | B12: 40807.6 | C12: 722 | D12: =$B$12/$C$12 -> 56.520222 | F12: This leads to us delving into the growth rate markers between the years and the analyses are as follows:
A13: East of England | B13: 41859.6 | C13: 745 | D13: =$B$13/$C$13 -> 56.187383 | F13: 1. While customer orders in the North East region grew by 20.67%, Sales and Profit grew by only 1.37% and 2.43% respectively.
A14: Scotland | B14: 57718.7 | C14: 999 | D14: =$B$14/$C$14 -> 57.776476 | F14: 2. Customer orders in the Northern Ireland grew by only 7.8%, sales and profit grew by 14.11% and 16.06% respectively.
A15: North West | B15: 58828.35 | C15: 1051 | D15: =$B$15/$C$15 -> 55.973692 | F15: 3. Across all product cateories, it is interesting to note that North East and Northern Ireland performed worst.
A16: Yorkshire & Humber | B16: 59211.55 | C16: 1017 | D16: =$B$16/$C$16 -> 58.22178 | F16: 4. Books category also brought in the least amount of sales and profit.
A17: South East | B17: 61259.85 | C17: 1045 | D17: =$B$17/$C$17 -> 58.621866
A18: London | B18: 104542.9 | C18: 1766 | D18: =$B$18/$C$18 -> 59.197565
A19: Grand Total | B19: 578786.2 | C19: 10000 | D19: =$B$19/$C$19 -> 57.87862
A20: MIN(per customer) | D20: =MIN(D7:D18) -> 55.869053
A24: YEAR | B24: (All)
A26: Row Labels | B26: Count of Order_ID | C26: Sum of Profit | D26: Sum of Sales | E26: Sum of Quantity
A27: Books | B27: 1264 | C27: 36120.7 | D27: 70758.7 | E27: 2308
A28: North East | B28: 41 | C28: 1140.9 | D28: 2192.9 | E28: 74
A29: Northern Ireland | B29: 60 | C29: 1728.9 | D29: 3409.9 | E29: 114
A30: Wales | B30: 66 | C30: 1919.9 | D30: 3776.9 | E30: 128
A31: West Midlands | B31: 84 | C31: 2444.7 | D31: 4865.7 | E31: 157
A32: South West | B32: 86 | C32: 2511.4 | D32: 4855.4 | E32: 156
A33: East of England | B33: 102 | C33: 2969.45 | D33: 5806.45 | E33: 181
A34: East Midlands | B34: 97 | C34: 2972.6 | D34: 5793.6 | E34: 189
A35: Scotland | B35: 121 | C35: 3024.9 | D35: 5934.9 | E35: 195
A36: North West | B36: 127 | C36: 3497 | D36: 6908 | E36: 228
A37: Yorkshire & Humber | B37: 124 | C37: 3576.55 | D37: 6965.55 | E37: 228
A38: South East | B38: 138 | C38: 3980.7 | D38: 7869.7 | E38: 260
... A105: Grand Total | B105: 10000 | C105: 578786.2 | D105: 1379032.2 | E105: 18381

Sheet Q1
A1: YEAR | B1: (All)
A3: Sum of Sales | B3: Sum of Profit | D3: Profit Margin
A4: 1379032.2 | B4: 578786.2 | D4: =$B$4/$A$4 -> 0.41970463
A6: Total Orders
A8: YEAR | B8: (All)
A10: Count of Order_ID | B10: Count of Customer_ID
A11: 10000 | B11: 10000

Sheet Q2
A1: YEAR | B1: 2025
A3: Row Labels | B3: Sum of Sales | C3: Sum of Profit | G3: Question: How did monthly revenue and profit change over the 2 year period.
A4: 1 | B4: 55687.75 | C4: 23709.75 | G4: Answer: Sales on the average remained between $50k and $60K over the two-year period except for a spike to nearly $70K in July of 2025. Profit on the other hand remianed consistent between $20K and $30K monthly over the two-years
A5: 2 | B5: 51382.85 | C5: 21445.85
A6: 3 | B6: 57232.25 | C6: 24199.25
A7: 4 | B7: 56452.85 | C7: 23771.85
A8: 5 | B8: 59003.75 | C8: 24274.75
A9: 6 | B9: 60369.45 | C9: 25790.45
A10: 7 | B10: 69073.15 | C10: 28587.15
A11: 8 | B11: 64069.8 | C11: 26275.8
A12: 9 | B12: 56125.1 | C12: 23377.1
A13: 10 | B13: 59904.25 | C13: 25084.25
A14: 11 | B14: 55638.1 | C14: 23157.1
A15: 12 | B15: 52129.05 | C15: 22007.05
A16: Grand Total | B16: 697068.35 | C16: 291680.35

Sheet Q3
A3: Row Labels | B3: Sum of Sales | C3: Sum of Profit
A4: Home & Kitchen | B4: 365777.75 | C4: 123953.75 | E4: QUESTION 3: Which product categories generate the most revenue?
A5: Electronics | B5: 318914.5 | C5: 127054.5 | E5: ANSWER: The pivot table shows which categories generated the most revenue over the 2 years. Home & Kitchen generated the most revenue.
A6: Clothing | B6: 227862.2 | C6: 105704.2
A7: Sports & Outdoors | B7: 216911.15 | C7: 93851.15
A8: Beauty | B8: 178807.9 | C8: 92101.9 | E8: QUESTION 4: Which product categories generate the most profit?
A9: Books | B9: 70758.7 | C9: 36120.7 | E9: ANSWER: The pivot table shows which categories generated the most profit over the 2 years. Electronics generated the most profit.
A10: Grand Total | B10: 1379032.2 | C10: 578786.2
E12: KEY INSIGHT: Though Home & Kitchen generated the most revenue, it accounts for less profit than Electronics.
E15: QUESTION 5: Which 10 products generate the most revenue, and which 10 generate the most profit?
A16: Row Labels | B16: Sum of Sales | C16: Sum of Profit | E16: ANSWER: | F16: The topTop 10 products for most profit and most revenue are highlighted on the pivot table.
A17: Smartwatch | B17: 137959.1 | C17: 48415.1
A18: Winter Jacket | B18: 96798 | C18: 42429
A19: Wireless Headphones | B19: 93347.65 | C19: 39587.65
A20: Air Fryer | B20: 100668.05 | C20: 35580.05
A21: Non-Stick Cookware Set | B21: 96562.95 | C21: 34318.95
A22: Running Shoes | B22: 85865.75 | C22: 33863.75
A23: Coffee Maker | B23: 74175.75 | C23: 27891.75
A24: Skincare Set | B24: 48691 | C24: 26391
A25: Robot Vacuum | B25: 94371 | C25: 26163
A26: Sneakers | B26: 55411.2 | C26: 25927.2
A27: Jeans | B27: 53784.25 | C27: 25720.25
A28: Perfume | B28: 51930.75 | C28: 25198.75
... A35: Yoga Mat | B35: 24648 | C35: 13140
A36: Cotton T-Shirt | B36: 21868.75 | C36: 11627.75 | T36: PROFIT MARGIN
A37: Cookbook Collection | B37: 22367.1 | C37: 11047.1 | T37: 0.42771726
A38: Data Analytics Handbook | B38: 21182 | C38: 10862 | T38: 0.42169399
A39: Business Strategy Book | B39: 17780 | C39: 8992 | T39: 0.42141655
A40: Personal Finance Guide | B40: 9429.6 | C40: 5219.6 | T40: 0.42117104
A41: Grand Total | B41: 1379032.2 | C41: 578786.2 | T41: 0.42057396
T42: 0.41988361
T43: 0.41918788
E44: QUESTION 6: Which regions generate the most revenue and profit? | T44: 0.4191206
A45: Row Labels | B45: Sum of Sales | C45: Sum of Profit | D45: PROFIT MARGIN | E45: ANSWER: The pivot table shows which regions generate the most revenue and profit. Top 3 are London, South East and Yorkshire&Humber | T45: 0.41874736
A46: East Midlands | B46: 97451.6 | C46: 40807.6 | D46: =_xlfn.PERCENTOF($C$46,$B$46) -> 0.41874736 | T46: 0.41706037
A47: East of England | B47: 99388.6 | C47: 41859.6 | D47: =_xlfn.PERCENTOF($C$47,$B$47) -> 0.42117104 | T47: 0.41595055
A48: London | B48: 249393.9 | C48: 104542.9 | D48: =_xlfn.PERCENTOF($C$48,$B$48) -> 0.41918788 | T48: 0.41528218
A49: North East | B49: 45552.65 | C49: 18947.65 | D49: =_xlfn.PERCENTOF($C$49,$B$49) -> 0.41595055 | E49: QUESTION 7: Which regions have the strongest and weakest profit margins?
A50: North West | B50: 139876.35 | C50: 58828.35 | D50: =_xlfn.PERCENTOF($C$50,$B$50) -> 0.42057396 | E50: ANSWER: West Midlands region has the strongest profit margin of 42.77% and Scotland has the lowest at 41.53%
A51: Northern Ireland | B51: 57614.3 | C51: 24191.3 | D51: =_xlfn.PERCENTOF($C$51,$B$51) -> 0.41988361
...

Sheet Product_Reference
A1: Product_ID | B1: Product_Name | C1: Category | D1: Unit_Price | E1: Unit_Cost
A2: P001 | B2: Wireless Headphones | C2: Electronics | D2: 89 | E2: 48
A3: P002 | B3: Smartwatch | C3: Electronics | D3: 149 | E3: 91
A4: P003 | B4: Bluetooth Speaker | C4: Electronics | D4: 69 | E4: 37
A5: P004 | B5: Laptop Stand | C5: Electronics | D5: 55 | E5: 27
A6: P005 | B6: Air Fryer | C6: Home & Kitchen | D6: 119 | E6: 72
A7: P006 | B7: Coffee Maker | C7: Home & Kitchen | D7: 99 | E7: 58
A8: P007 | B8: Non-Stick Cookware Set | C8: Home & Kitchen | D8: 129 | E8: 78
A9: P008 | B9: Robot Vacuum | C9: Home & Kitchen | D9: 249 | E9: 168
A10: P009 | B10: Running Shoes | C10: Sports & Outdoors | D10: 95 | E10: 54
A11: P010 | B11: Yoga Mat | C11: Sports & Outdoors | D11: 32 | E11: 14
A12: P011 | B12: Fitness Tracker | C12: Sports & Outdoors | D12: 79 | E12: 42
A13: P012 | B13: Camping Backpack | C13: Sports & Outdoors | D13: 85 | E13: 44
... A25: P024 | B25: Personal Finance Guide | C25: Books | D25: 24 | E25: 10
